{"name": "Нельзя авторизоваться под существующим пользователем", "status": "passed", "description": "Для ревьюера: здесь баг, вторая авторизация проходит, если уже авторизован", "start": 1719570389020, "stop": 1719570390053, "uuid": "0a683bc8-8ba7-4299-ad39-5056385b66fd", "historyId": "3f3cc886f69e0c03d66504d93a31a5bd", "testCaseId": "3f3cc886f69e0c03d66504d93a31a5bd", "fullName": "tests.test_login_user.TestLoginUser#test_re_login_user_code_401", "labels": [{"name": "parentSuite", "value": "tests"}, {"name": "suite", "value": "test_login_user"}, {"name": "subSuite", "value": "TestLoginUser"}, {"name": "host", "value": "DESKTOP-USF6L0H"}, {"name": "thread", "value": "15232-MainThread"}, {"name": "framework", "value": "pytest"}, {"name": "language", "value": "cpython3"}, {"name": "package", "value": "tests.test_login_user"}]}